<?xml version="1.0"?>
<robot name="robot1">

  <!-- World link (ground) -->
  <link name="world1"/>

  <!-- Base link -->
  <link name="base1_link">
    <visual>
      <geometry>
        <box size="0.4 0.4 0.2"/>
      </geometry>
      <origin xyz="0 0 0.1" rpy="0 0 0"/>
      <material name="blue">
        <color rgba="0 0 1 1"/>
      </material>
    </visual>
    <collision>
      <geometry>
        <box size="0.4 0.4 0.2"/>
      </geometry>
      <origin xyz="0 0 0.1" rpy="0 0 0"/>
    </collision>
    <inertial>
      <mass value="2.0"/>
      <inertia ixx="0.05" ixy="0" ixz="0" iyy="0.05" iyz="0" izz="0.1"/>
      <origin xyz="0 0 0.1" rpy="0 0 0"/>
    </inertial>
  </link>

  <!-- Fixed joint to world -->
  <joint name="base_to_world" type="fixed">
    <parent link="world1"/>
    <child link="base1_link"/>
    <origin xyz="0 0 0" rpy="0 0 0"/>
  </joint>

  <!-- Arm link 1 -->
  <link name="arm_link1">
    <visual>
      <geometry>
        <cylinder radius="0.05" length="0.3"/>
      </geometry>
      <origin xyz="0 0 0.15" rpy="0 1.57 0"/>
      <material name="red">
        <color rgba="1 0 0 1"/>
      </material>
    </visual>
    <collision>
      <geometry>
        <cylinder radius="0.05" length="0.3"/>
      </geometry>
      <origin xyz="0 0 0.15" rpy="0 1.57 0"/>
    </collision>
    <inertial>
      <mass value="1.0"/>
      <inertia ixx="0.01" ixy="0" ixz="0" iyy="0.01" iyz="0" izz="0.001"/>
      <origin xyz="0 0 0.15" rpy="0 1.57 0"/>
    </inertial>
  </link>

  <!-- Revolute joint -->
  <joint name="arm_joint1" type="revolute">
    <parent link="base1_link"/>
    <child link="arm_link1"/>
    <origin xyz="0.2 0 0.1" rpy="0 0 0"/>
    <axis xyz="0 1 0"/>
    <limit lower="-1.57" upper="1.57" effort="10" velocity="1.0"/>
  </joint>

  <!-- Arm link 2 -->
  <link name="arm_link2">
    <visual>
      <geometry>
        <cylinder radius="0.04" length="0.25"/>
      </geometry>
      <origin xyz="0 0 0.125" rpy="0 1.57 0"/>
      <material name="green">
        <color rgba="0 1 0 1"/>
      </material>
    </visual>
    <collision>
      <geometry>
        <cylinder radius="0.04" length="0.25"/>
      </geometry>
      <origin xyz="0 0 0.125" rpy="0 1.57 0"/>
    </collision>
    <inertial>
      <mass value="0.5"/>
      <inertia ixx="0.005" ixy="0" ixz="0" iyy="0.005" iyz="0" izz="0.0005"/>
      <origin xyz="0 0 0.125" rpy="0 1.57 0"/>
    </inertial>
  </link>

  <!-- Second revolute joint -->
  <joint name="arm_joint2" type="revolute">
    <parent link="arm_link1"/>
    <child link="arm_link2"/>
    <origin xyz="0.3 0 0" rpy="0 0 0"/>
    <axis xyz="0 1 0"/>
    <limit lower="-1.57" upper="1.57" effort="5" velocity="1.0"/>
  </joint>


  <gazebo>
    <plugin filename="gz-sim-joint-state-publisher-system" name="gz::sim::systems::JointStatePublisher">
        <topic>/joint_states</topic>
        <joint_name>arm_joint1</joint_name>
        <joint_name>arm_joint2</joint_name>
    </plugin> 
  </gazebo>

</robot>